Workbook

Sheet DATOS_ANALISIS
A1: CANCHA | B1: JUGADOR | C1: POSICION | D1: PUNTOS | H1: Etiquetas de fila | I1: Suma de PUNTOS
A2: 1 | B2: Andrea Julieth Sosa Rodriguez | C2: DERECHA | D2: 7 | F2: =IF(G2=1,"🥇",IF(G2=2,"🥈",IF(G2=3,"🥉",IF(G2=4,"🏅","")))) -> 🥇 | G2: 1 | H2: Nicole Lizarazo | I2: 35
A3: 1 | B3: Daniel Gutierrez | C3: DERECHA | D3: 2 | F3: =IF(G3=1,"🥇",IF(G3=2,"🥈",IF(G3=3,"🥉",IF(G3=4,"🏅","")))) -> 🥈 | G3: 2 | H3: Santiago Gutiérrez de Piñeres Barbosa | I3: 34
A4: 1 | B4: David Santiago Medina Buitrago | C4: DERECHA | D4: 14 | F4: =IF(G4=1,"🥇",IF(G4=2,"🥈",IF(G4=3,"🥉",IF(G4=4,"🏅","")))) -> 🥉 | G4: 3 | H4: Juan Pablo Benitez Bernal | I4: 34
A5: 1 | B5: David Santiago Murcia Barrera | C5: IZQUIERDA | D5: 1 | F5: =IF(G5=1,"🥇",IF(G5=2,"🥈",IF(G5=3,"🥉",IF(G5=4,"🏅","")))) -> 🏅 | G5: 4 | H5: Sergio Andrés López Rodríguez | I5: 33
A6: 1 | B6: Jaime Andres Castillo Alvarez | C6: IZQUIERDA | D6: 4 | F6: =IF(G6=1,"🥇",IF(G6=2,"🥈",IF(G6=3,"🥉",IF(G6=4,"🏅","")))) | G6: 5 | H6: Samuel Andrés Rodríguez Ulloa | I6: 33
A7: 1 | B7: Jaime Andres Castillo Alvarez | C7: DERECHA | D7: 9 | F7: =IF(G7=1,"🥇",IF(G7=2,"🥈",IF(G7=3,"🥉",IF(G7=4,"🏅","")))) | G7: 6 | H7: Jorge Enrique Lugo Lopez | I7: 32
A8: 1 | B8: Jorge Enrique Lugo Lopez | C8: DERECHA | D8: 7 | F8: =IF(G8=1,"🥇",IF(G8=2,"🥈",IF(G8=3,"🥉",IF(G8=4,"🏅","")))) | G8: 7 | H8: Tomas Barrios Guevara | I8: 32
A9: 1 | B9: juan miguel venegas garzón | C9: IZQUIERDA | D9: 4 | F9: =IF(G9=1,"🥇",IF(G9=2,"🥈",IF(G9=3,"🥉",IF(G9=4,"🏅","")))) | G9: 8 | H9: Luis Mario Ramirez Muñoz | I9: 31
A10: 1 | B10: Juan Pablo Aponte Veloza | C10: DERECHA | D10: 7 | F10: =IF(G10=1,"🥇",IF(G10=2,"🥈",IF(G10=3,"🥉",IF(G10=4,"🏅","")))) | G10: 9 | H10: Luis Jorge Garcia Camargo | I10: 31
A11: 1 | B11: Juliana Beltrán Díaz | C11: IZQUIERDA | D11: 7 | F11: =IF(G11=1,"🥇",IF(G11=2,"🥈",IF(G11=3,"🥉",IF(G11=4,"🏅","")))) | G11: 10 | H11: Fermin Alejandro Escalona Guillen | I11: 30
A12: 1 | B12: Luis Mario Ramirez Muñoz | C12: IZQUIERDA | D12: 7 | F12: =IF(G12=1,"🥇",IF(G12=2,"🥈",IF(G12=3,"🥉",IF(G12=4,"🏅","")))) | G12: 11 | H12: Juan Pablo Vargas Jiménez | I12: 30
A13: 1 | B13: María José Cifuentes | C13: DERECHA | D13: 5 | F13: =IF(G13=1,"🥇",IF(G13=2,"🥈",IF(G13=3,"🥉",IF(G13=4,"🏅","")))) | G13: 12 | H13: maria jose martinez villabona | I13: 29
... A37: 1 | B37: Andrea Julieth Sosa Rodriguez | C37: IZQUIERDA | D37: 6 | F37: =IF(G37=1,"🥇",IF(G37=2,"🥈",IF(G37=3,"🥉",IF(G37=4,"🏅","")))) | G37: 36 | H37: Daniel Gutierrez | I37: 12
A38: 1 | B38: Carlos Felipe Andrade Sáenz | C38: IZQUIERDA | D38: 1 | H38: Total general | I38: 938
A39: 1 | B39: Carlos Felipe Andrade Sáenz | C39: DERECHA | D39: 17
A40: 1 | B40: Daniel Gutierrez | C40: IZQUIERDA | D40: 6
A41: 1 | B41: David Santiago Murcia Barrera | C41: IZQUIERDA | D41: 5
A42: 1 | B42: Isabella Buitrago Hurtado | C42: IZQUIERDA | D42: 6
A43: 1 | B43: Jonatan Nicolas Marmolejo Lopez | C43: IZQUIERDA | D43: 7
A44: 1 | B44: Juan Pablo Benitez Bernal | C44: IZQUIERDA | D44: 7
A45: 1 | B45: Juan Pablo Vargas Jiménez | C45: DERECHA | D45: 7
A46: 1 | B46: Luis Jorge Garcia Camargo | C46: IZQUIERDA | D46: 5
A47: 1 | B47: Nicole Lizarazo | C47: IZQUIERDA | D47: 7
A48: 1 | B48: Nicole Lizarazo | C48: DERECHA | D48: 14
A49: 1 | B49: Samuel Andrés Rodríguez Ulloa | C49: DERECHA | D49: 5
A50: 1 | B50: Sergio Andrés López Rodríguez | C50: DERECHA | D50: 7
... A142: 2 | B142: Valentina Jimenez Gomez | C142: DERECHA | D142: 9

Sheet TD
A5: CANCHA | B5: ID_JUGADOR_1_EQUIPO_1 | C5: POSICION_JUGADOR_1_EQUIPO_1 | D5: Suma de PUNTO_EQUIPO_1 | F5: CANCHA | G5: ID_JUGADOR_2_EQUIPO_1 | H5: POSICION_JUGADOR_2_EQUIPO_1 | I5: Suma de PUNTO_EQUIPO_1 | L5: CANCHA | M5: ID_JUGADOR_1_EQUIPO_2 | N5: POSICION_JUGADOR_1_EQUIPO_2 | O5: Suma de PUNTO_EQUIPO_2 | Q5: CANCHA | R5: ID_JUGADOR_2_EQUIPO_2 | S5: POSICION_JUGADOR_2_EQUIPO_2 | T5: Suma de PUNTO_EQUIPO_2
A6: 1 | B6: Andrea Julieth Sosa Rodriguez | C6: DERECHA | D6: 7 | F6: 1 | G6: Cristian Stevan Soto Zapata | H6: IZQUIERDA | I6: 13 | L6: 1 | M6: Andrea Julieth Sosa Rodriguez | N6: IZQUIERDA | O6: 6 | Q6: 1 | R6: Andrea Julieth Sosa Rodriguez | T6: 5
A7: 1 | B7: Daniel Gutierrez | C7: DERECHA | D7: 2 | F7: 1 | G7: Daniel Gutierrez | H7: IZQUIERDA | I7: 2 | L7: 1 | M7: Carlos Felipe Andrade Sáenz | N7: IZQUIERDA | O7: 1 | Q7: 1 | R7: César Camilo Díaz Cufiño | S7: DERECHA | T7: 11
A8: 1 | B8: David Santiago Medina Buitrago | C8: DERECHA | D8: 14 | F8: 1 | G8: David Santiago Murcia Barrera | H8: IZQUIERDA | I8: 5 | L8: 1 | M8: Carlos Felipe Andrade Sáenz | N8: DERECHA | O8: 17 | Q8: 1 | R8: Cristian Stevan Soto Zapata | S8: IZQUIERDA | T8: 7
A9: 1 | B9: David Santiago Murcia Barrera | C9: IZQUIERDA | D9: 1 | F9: 1 | G9: Fermin Alejandro Escalona Guillen | H9: IZQUIERDA | I9: 13 | L9: 1 | M9: Daniel Gutierrez | N9: IZQUIERDA | O9: 6 | Q9: 1 | R9: Fermin Alejandro Escalona Guillen | S9: DERECHA | T9: 7
A10: 1 | B10: Jaime Andres Castillo Alvarez | C10: IZQUIERDA | D10: 4 | F10: 1 | G10: Fermin Alejandro Escalona Guillen | H10: DERECHA | I10: 4 | L10: 1 | M10: David Santiago Murcia Barrera | N10: IZQUIERDA | O10: 5 | Q10: 1 | R10: Jorge Enrique Lugo Lopez | S10: IZQUIERDA | T10: 7
A11: 1 | B11: Jaime Andres Castillo Alvarez | C11: DERECHA | D11: 9 | F11: 1 | G11: Isabella Buitrago Hurtado | H11: IZQUIERDA | I11: 7 | L11: 1 | M11: Isabella Buitrago Hurtado | N11: IZQUIERDA | O11: 6 | Q11: 1 | R11: Jorge Enrique Lugo Lopez | S11: DERECHA | T11: 7
A12: 1 | B12: Jorge Enrique Lugo Lopez | C12: DERECHA | D12: 7 | F12: 1 | G12: Isabella Buitrago Hurtado | H12: DERECHA | I12: 1 | L12: 1 | M12: Jonatan Nicolas Marmolejo Lopez | N12: IZQUIERDA | O12: 7 | Q12: 1 | R12: Juan Pablo Benitez Bernal | S12: IZQUIERDA | T12: 14
A13: 1 | B13: juan miguel venegas garzón | C13: IZQUIERDA | D13: 4 | F13: 1 | G13: Jaime Andres Castillo Alvarez | H13: IZQUIERDA | I13: 7 | L13: 1 | M13: Juan Pablo Benitez Bernal | N13: IZQUIERDA | O13: 7 | Q13: 1 | R13: Juan Pablo Vargas Jiménez | S13: DERECHA | T13: 6
A14: 1 | B14: Juan Pablo Aponte Veloza | C14: DERECHA | D14: 7 | F14: 1 | G14: Juan Pablo Aponte Veloza | H14: IZQUIERDA | I14: 2 | L14: 1 | M14: Juan Pablo Vargas Jiménez | N14: DERECHA | O14: 7 | Q14: 1 | R14: Luis Jorge Garcia Camargo | S14: DERECHA | T14: 5
A15: 1 | B15: Juliana Beltrán Díaz | C15: IZQUIERDA | D15: 7 | F15: 1 | G15: Juan Pablo Benitez Bernal | H15: DERECHA | I15: 7 | L15: 1 | M15: Luis Jorge Garcia Camargo | N15: IZQUIERDA | O15: 5 | Q15: 1 | R15: María José Cifuentes | S15: IZQUIERDA | T15: 11
A16: 1 | B16: Luis Mario Ramirez Muñoz | C16: IZQUIERDA | D16: 7 | F16: 1 | G16: Maria Fernanda Tamayo Lopez | H16: DERECHA | I16: 7 | L16: 1 | M16: Nicole Lizarazo | N16: IZQUIERDA | O16: 7 | Q16: 1 | R16: Nikol sofia avendaño | S16: DERECHA | T16: 5
A17: 1 | B17: María José Cifuentes | C17: DERECHA | D17: 5 | F17: 1 | G17: María José Cifuentes | H17: IZQUIERDA | I17: 1 | L17: 1 | M17: Nicole Lizarazo | N17: DERECHA | O17: 14 | Q17: 1 | R17: Samuel Andrés Rodríguez Ulloa | S17: DERECHA | T17: 7
A18: 1 | B18: Nicole Lizarazo | C18: IZQUIERDA | D18: 7 | F18: 1 | G18: maria jose martinez villabona | H18: IZQUIERDA | I18: 7 | L18: 1 | M18: Samuel Andrés Rodríguez Ulloa | N18: DERECHA | O18: 5 | Q18: 1 | R18: Santiago Navarro Cuy | S18: IZQUIERDA | T18: 7
... A22: 1 | B22: Valentina Alejandra Lopez Romero | C22: DERECHA | D22: 11 | F22: 1 | G22: Santiago Urrego Rodríguez | H22: IZQUIERDA | I22: 5 | L22: 1 | M22: Valentina Jimenez Gomez | N22: IZQUIERDA | O22: 5 | Q22: 1 | R22: Valentina Jimenez Gomez | S22: DERECHA | T22: 6
A23: Total general | D23: 105 | F23: 1 | G23: Valentina Alejandra Lopez Romero | H23: DERECHA | I23: 7 | L23: Total general | O23: 117 | Q23: Total general | T23: 117
F24: Grand Total | I24: 105
A31: CANCHA | B31: ID_JUGADOR_1_EQUIPO_1 | C31: POSICION_JUGADOR_1_EQUIPO_1 | D31: Suma de PUNTO_EQUIPO_1 | F31: CANCHA | G31: ID_JUGADOR_2_EQUIPO_1 | H31: POSICION_JUGADOR_2_EQUIPO_1 | I31: Suma de PUNTO_EQUIPO_1 | L31: CANCHA | M31: ID_JUGADOR_1_EQUIPO_2 | N31: POSICION_JUGADOR_1_EQUIPO_2 | O31: Suma de PUNTO_EQUIPO_2 | Q31: CANCHA | R31: ID_JUGADOR_2_EQUIPO_2 | S31: POSICION_JUGADOR_2_EQUIPO_2 | T31: Suma de PUNTO_EQUIPO_2
A32: 2 | B32: Andrea Julieth Sosa Rodriguez | C32: IZQUIERDA | D32: 7 | F32: 2 | G32: Carlos Felipe Andrade Sáenz | H32: DERECHA | I32: 6 | L32: 2 | M32: César Camilo Díaz Cufiño | N32: IZQUIERDA | O32: 7 | Q32: 2 | R32: César Camilo Díaz Cufiño | S32: DERECHA | T32: 10
A33: 2 | B33: Cristian Stevan Soto Zapata | C33: IZQUIERDA | D33: 7 | F33: 2 | G33: Isabella Buitrago Hurtado | H33: DERECHA | I33: 2 | L33: 2 | M33: Cristian Stevan Soto Zapata | N33: IZQUIERDA | O33: 2 | Q33: 2 | R33: David Santiago Medina Buitrago | S33: IZQUIERDA | T33: 13
A34: 2 | B34: Daniel Gutierrez | C34: IZQUIERDA | D34: 2 | F34: 2 | G34: Jonatan Nicolas Marmolejo Lopez | H34: IZQUIERDA | I34: 10 | L34: 2 | M34: David Santiago Medina Buitrago | N34: DERECHA | O34: 2 | Q34: 2 | R34: Jaime Andres Castillo Alvarez | S34: IZQUIERDA | T34: 7
A35: 2 | B35: David Santiago Murcia Barrera | C35: IZQUIERDA | D35: 2 | F35: 2 | G35: Jorge Enrique Lugo Lopez | H35: DERECHA | I35: 4 | L35: 2 | M35: Fermin Alejandro Escalona Guillen | N35: DERECHA | O35: 6 | Q35: 2 | R35: Jorge Enrique Lugo Lopez | S35: IZQUIERDA | T35: 7
A36: 2 | B36: Juliana Beltrán Díaz | C36: DERECHA | D36: 9 | F36: 2 | G36: juan miguel venegas garzón | H36: DERECHA | I36: 14 | L36: 2 | M36: Isabella Buitrago Hurtado | N36: IZQUIERDA | O36: 7 | Q36: 2 | R36: Juan Pablo Aponte Veloza | S36: DERECHA | T36: 9
A37: 2 | B37: Luis Mario Ramirez Muñoz | C37: IZQUIERDA | D37: 13 | F37: 2 | G37: Juan Pablo Aponte Veloza | H37: IZQUIERDA | I37: 2 | L37: 2 | M37: Jonatan Nicolas Marmolejo Lopez | N37: DERECHA | O37: 7 | Q37: 2 | R37: Juan Pablo Vargas Jiménez | S37: IZQUIERDA | T37: 8
A38: 2 | B38: Maria Fernanda Tamayo Lopez | C38: DERECHA | D38: 2 | F38: 2 | G38: Juan Pablo Vargas Jiménez | H38: DERECHA | I38: 5 | L38: 2 | M38: juan miguel venegas garzón | N38: DERECHA | O38: 5 | Q38: 2 | R38: Luis Mario Ramirez Muñoz | S38: IZQUIERDA | T38: 7
A39: 2 | B39: María José Cifuentes | C39: IZQUIERDA | D39: 7 | F39: 2 | G39: Juan Pablo Vargas Jiménez | H39: IZQUIERDA | I39: 4 | L39: 2 | M39: Juan Pablo Benitez Bernal | N39: IZQUIERDA | O39: 6 | Q39: 2 | R39: maria jose martinez villabona | S39: IZQUIERDA | T39: 6
A40: 2 | B40: Nicolas Navarro | C40: IZQUIERDA | D40: 10 | F40: 2 | G40: Juliana Beltrán Díaz | H40: DERECHA | I40: 2 | L40: 2 | M40: Juliana Beltrán Díaz | N40: DERECHA | O40: 7 | Q40: 2 | R40: Nicolas Navarro | S40: DERECHA | T40: 7
A41: 2 | B41: Rafael Andres Salcedo Valdivieso | C41: DERECHA | D41: 14 | F41: 2 | G41: Luis Jorge Garcia Camargo | H41: DERECHA | I41: 7 | L41: 2 | M41: Luis Jorge Garcia Camargo | N41: DERECHA | O41: 7 | Q41: 2 | R41: Nicolas Navarro | S41: IZQUIERDA | T41: 4
A42: 2 | B42: Samuel Andrés Rodríguez Ulloa | C42: DERECHA | D42: 7 | F42: 2 | G42: Luis Jorge Garcia Camargo | H42: IZQUIERDA | I42: 7 | L42: 2 | M42: Luis Mario Ramirez Muñoz | N42: IZQUIERDA | O42: 4 | Q42: 2 | R42: Nikol sofia avendaño | S42: IZQUIERDA | T42: 6
A43: 2 | B43: Santiago Navarro Cuy | C43: IZQUIERDA | D43: 8 | F43: 2 | G43: Maria Fernanda Tamayo Lopez | H43: DERECHA | I43: 6 | L43: 2 | M43: Maria Fernanda Tamayo Lopez | N43: DERECHA | O43: 14 | Q43: 2 | R43: Rafael Andres Salcedo Valdivieso | S43: DERECHA | T43: 7
... A47: 2 | B47: Sergio Andrés López Rodríguez | C47: IZQUIERDA | D47: 7 | F47: 2 | G47: Santiago Gutiérrez de Piñeres Barbosa | H47: DERECHA | I47: 7 | L47: 2 | M47: Santiago Navarro Cuy | N47: IZQUIERDA | O47: 2 | Q47: 2 | R47: Sergio Andrés López Rodríguez | S47: IZQUIERDA | T47: 12
A48: Total general | D48: 117 | F48: 2 | G48: Santiago Peña Beltran | H48: DERECHA | I48: 1 | L48: 2 | M48: sara juliana solano boada | N48: IZQUIERDA | O48: 7 | Q48: 2 | R48: Valentina Alejandra Lopez Romero | S48: IZQUIERDA | T48: 2
F49: 2 | G49: sara juliana solano boada | H49: DERECHA | I49: 7 | L49: 2 | M49: Tomas Barrios Guevara | N49: IZQUIERDA | O49: 14 | Q49: 2 | R49: Valentina Jimenez Gomez | S49: DERECHA | T49: 9
F50: 2 | G50: Sergio Andrés López Rodríguez | H50: IZQUIERDA | I50: 7 | L50: Total general | O50: 130 | Q50: Total general | T50: 130
F51: 2 | G51: Valentina Jimenez Gomez | H51: IZQUIERDA | I51: 6
F52: Total general | I52: 117

Sheet Cancha
A1: ID_PARTIDO | B1: CANCHA | C1: ID_PUNTO | D1: ID_JUGADOR_1_EQUIPO_1 | E1: ID_JUGADOR_2_EQUIPO_1 | F1: ID_JUGADOR_1_EQUIPO_2 | G1: ID_JUGADOR_2_EQUIPO_2 | H1: POSICION_JUGADOR_1_EQUIPO_1 | I1: POSICION_JUGADOR_2_EQUIPO_1 | J1: POSICION_JUGADOR_1_EQUIPO_2 | K1: POSICION_JUGADOR_2_EQUIPO_2 | L1: PUNTO_EQUIPO_1 | M1: PUNTO_EQUIPO_2
A2: 2 | B2: 2 | C2: 1 | D2: Luis Mario Ramirez Munoz | E2: Santiago Gutierrez de Pineres | F2: Nikol sofia avendano | G2: =VLOOKUP(Tabla138[[#This Row],[ID_PARTIDO]],Original!$AT$1:$AY$46,5,FALSE) -> Valentina Jimenez Gomez | H2: IZQUIERDA | I2: DERECHA | J2: IZQUIERDA | K2: DERECHA | L2: 1 | M2: 0 | Q2: ID_JUGADOR_1_EQUIPO_1 | R2: ID_PARTIDO | S2: Suma de PUNTO_EQUIPO_1 | V2: ID_JUGADOR_2_EQUIPO_1 | W2: ID_PARTIDO | X2: Suma de PUNTO_EQUIPO_1 | Z2: ID_JUGADOR_1_EQUIPO_2 | AA2: ID_PARTIDO | AB2: Suma de PUNTO_EQUIPO_2 | AD2: ID_JUGADOR_2_EQUIPO_2 | AE2: ID_PARTIDO | AF2: Suma de PUNTO_EQUIPO_2
A3: 2 | B3: 2 | C3: 2 | D3: Luis Mario Ramirez Munoz | E3: Santiago Gutierrez de Pineres | F3: Nikol sofia avendano | G3: =VLOOKUP(Tabla138[[#This Row],[ID_PARTIDO]],Original!$AT$1:$AY$46,5,FALSE) -> Valentina Jimenez Gomez | H3: IZQUIERDA | I3: DERECHA | J3: IZQUIERDA | K3: DERECHA | L3: 1 | M3: 0 | Q3: Andrea Julieth Sosa Rodriguez | R3: 30 | S3: 7 | V3: Carlos Felipe Andrade Saenz | W3: 6 | X3: 6 | Z3: César Camilo Díaz Cufiño | AA3: 24 | AB3: 7 | AD3: César Camilo Díaz Cufiño | AE3: 14 | AF3: 4
A4: 2 | B4: 2 | C4: 3 | D4: Luis Mario Ramirez Munoz | E4: Santiago Gutierrez de Pineres | F4: Nikol sofia avendano | G4: =VLOOKUP(Tabla138[[#This Row],[ID_PARTIDO]],Original!$AT$1:$AY$46,5,FALSE) -> Valentina Jimenez Gomez | H4: IZQUIERDA | I4: DERECHA | J4: IZQUIERDA | K4: DERECHA | L4: 1 | M4: 0 | Q4: Cristian Stevan Soto Zapata | R4: 32 | S4: 7 | V4: Isabella Buitrago Hurtado | W4: 26 | X4: 2 | Z4: Cristian Stevan Soto Zapata | AA4: 42 | AB4: 2 | AD4: César Camilo Díaz Cufiño | AE4: 30 | AF4: 6
A5: 2 | B5: 2 | C5: 4 | D5: Luis Mario Ramirez Munoz | E5: Santiago Gutierrez de Pineres | F5: Nikol sofia avendano | G5: =VLOOKUP(Tabla138[[#This Row],[ID_PARTIDO]],Original!$AT$1:$AY$46,5,FALSE) -> Valentina Jimenez Gomez | H5: IZQUIERDA | I5: DERECHA | J5: IZQUIERDA | K5: DERECHA | L5: 0 | M5: 1 | Q5: Daniel Gutierrez | R5: 26 | S5: 2 | V5: Jonatan Nicolas Marmolejo Lopez | W5: 18 | X5: 3 | Z5: David Santiago Medina Buitrago | AA5: 28 | AB5: 2 | AD5: David Santiago Medina Buitrago | AE5: 6 | AF5: 6
A6: 2 | B6: 2 | C6: 5 | D6: Luis Mario Ramirez Munoz | E6: Santiago Gutierrez de Pineres | F6: Nikol sofia avendano | G6: =VLOOKUP(Tabla138[[#This Row],[ID_PARTIDO]],Original!$AT$1:$AY$46,5,FALSE) -> Valentina Jimenez Gomez | H6: IZQUIERDA | I6: DERECHA | J6: IZQUIERDA | K6: DERECHA | L6: 1 | M6: 0 | Q6: David Santiago Murcia Barrera | R6: 36 | S6: 2 | V6: Jonatan Nicolas Marmolejo Lopez | W6: 28 | X6: 7 | Z6: Fermin Alejandro Escalona Guillen | AA6: 6 | AB6: 6 | AD6: David Santiago Medina Buitrago | AE6: 40 | AF6: 7
A7: 2 | B7: 2 | C7: 6 | D7: Luis Mario Ramirez Munoz | E7: Santiago Gutierrez de Pineres | F7: Nikol sofia avendano | G7: =VLOOKUP(Tabla138[[#This Row],[ID_PARTIDO]],Original!$AT$1:$AY$46,5,FALSE) -> Valentina Jimenez Gomez | H7: IZQUIERDA | I7: DERECHA | J7: IZQUIERDA | K7: DERECHA | L7: 0 | M7: 1 | Q7: Jaime Andres Castillo Alvarez | R7: 37 | S7: 4 | V7: Jorge Enrique Lugo Lopez | W7: 24 | X7: 4 | Z7: Isabella Buitrago Hurtado | AA7: 22 | AB7: 7 | AD7: Jaime Andres Castillo Alvarez | AE7: 18 | AF7: 7
A8: 2 | B8: 2 | C8: 7 | D8: Luis Mario Ramirez Munoz | E8: Santiago Gutierrez de Pineres | F8: Nikol sofia avendano | G8: =VLOOKUP(Tabla138[[#This Row],[ID_PARTIDO]],Original!$AT$1:$AY$46,5,FALSE) -> Valentina Jimenez Gomez | H8: IZQUIERDA | I8: DERECHA | J8: IZQUIERDA | K8: DERECHA | L8: 1 | M8: 0 | Q8: Juliana Beltrán Díaz | R8: 18 | S8: 3 | V8: juan miguel venegas garzón | W8: 30 | X8: 7 | Z8: Jonatan Nicolas Marmolejo Lopez | AA8: 40 | AB8: 7 | AD8: Jorge Enrique Lugo Lopez | AE8: 38 | AF8: 7
A9: 2 | B9: 2 | C9: 8 | D9: Luis Mario Ramirez Munoz | E9: Santiago Gutierrez de Pineres | F9: Nikol sofia avendano | G9: =VLOOKUP(Tabla138[[#This Row],[ID_PARTIDO]],Original!$AT$1:$AY$46,5,FALSE) -> Valentina Jimenez Gomez | H9: IZQUIERDA | I9: DERECHA | J9: IZQUIERDA | K9: DERECHA | L9: 1 | M9: 0 | Q9: Juliana Beltrán Díaz | R9: 22 | S9: 6 | V9: juan miguel venegas garzón | W9: 42 | X9: 7 | Z9: juan miguel venegas garzón | AA9: 32 | AB9: 5 | AD9: Juan Pablo Aponte Veloza | AE9: 4 | AF9: 2
A10: 2 | B10: 2 | C10: 9 | D10: Luis Mario Ramirez Munoz | E10: Santiago Gutierrez de Pineres | F10: Nikol sofia avendano | G10: =VLOOKUP(Tabla138[[#This Row],[ID_PARTIDO]],Original!$AT$1:$AY$46,5,FALSE) -> Valentina Jimenez Gomez | H10: IZQUIERDA | I10: DERECHA | J10: IZQUIERDA | K10: DERECHA | L10: 1 | M10: 0 | Q10: Luis Mario Ramirez Munoz | R10: 2 | S10: 7 | V10: Juan Pablo Aponte Veloza | W10: 44 | X10: 2 | Z10: Juan Pablo Benitez Bernal | AA10: 30 | AB10: 6 | AD10: Juan Pablo Aponte Veloza | AE10: 20 | AF10: 7
A11: 6 | B11: 2 | C11: 1 | D11: Luis Mario Ramirez Munoz | E11: Carlos Felipe Andrade Saenz | F11: =VLOOKUP(Tabla138[[#This Row],[ID_PARTIDO]],Original!$AT$1:$AY$46,4,FALSE) -> Fermin Alejandro Escalona Guillen | G11: =VLOOKUP(Tabla138[[#This Row],[ID_PARTIDO]],Original!$AT$1:$AY$46,5,FALSE) -> David Santiago Medina Buitrago | H11: IZQUIERDA | I11: DERECHA | J11: DERECHA | K11: IZQUIERDA | L11: 0 | M11: 1 | Q11: Luis Mario Ramirez Munoz | R11: 6 | S11: 6 | V11: Juan Pablo Vargas Jiménez | W11: 20 | X11: 5 | Z11: Juliana Beltrán Díaz | AA11: 44 | AB11: 7 | AD11: Juan Pablo Benitez Bernal | AE11: 37 | AF11: 7
A12: 6 | B12: 2 | C12: 2 | D12: Luis Mario Ramirez Munoz | E12: Carlos Felipe Andrade Saenz | F12: =VLOOKUP(Tabla138[[#This Row],[ID_PARTIDO]],Original!$AT$1:$AY$46,4,FALSE) -> Fermin Alejandro Escalona Guillen | G12: =VLOOKUP(Tabla138[[#This Row],[ID_PARTIDO]],Original!$AT$1:$AY$46,5,FALSE) -> David Santiago Medina Buitrago | H12: IZQUIERDA | I12: DERECHA | J12: DERECHA | K12: IZQUIERDA | L12: 1 | M12: 0 | Q12: Maria Fernanda Tamayo Lopez | R12: 44 | S12: 2 | V12: Juan Pablo Vargas Jiménez | W12: 40 | X12: 4 | Z12: Luis Jorge Garcia Camargo | AA12: 12 | AB12: 7 | AD12: Juan Pablo Vargas Jiménez | AE12: 39 | AF12: 8
A13: 6 | B13: 2 | C13: 3 | D13: Luis Mario Ramirez Munoz | E13: Carlos Felipe Andrade Saenz | F13: =VLOOKUP(Tabla138[[#This Row],[ID_PARTIDO]],Original!$AT$1:$AY$46,4,FALSE) -> Fermin Alejandro Escalona Guillen | G13: =VLOOKUP(Tabla138[[#This Row],[ID_PARTIDO]],Original!$AT$1:$AY$46,5,FALSE) -> David Santiago Medina Buitrago | H13: IZQUIERDA | I13: DERECHA | J13: DERECHA | K13: IZQUIERDA | L13: 0 | M13: 1 | Q13: María José Cifuentes | R13: 14 | S13: 7 | V13: Juliana Beltrán Díaz | W13: 36 | X13: 2 | Z13: Luis Mario Ramirez Muñoz | AA13: 14 | AB13: 4 | AD13: Luis Mario Ramirez Munoz | AE13: 44 | AF13: 7
A14: 6 | B14: 2 | C14: 4 | D14: Luis Mario Ramirez Munoz | E14: Carlos Felipe Andrade Saenz | F14: =VLOOKUP(Tabla138[[#This Row],[ID_PARTIDO]],Original!$AT$1:$AY$46,4,FALSE) -> Fermin Alejandro Escalona Guillen | G14: =VLOOKUP(Tabla138[[#This Row],[ID_PARTIDO]],Original!$AT$1:$AY$46,5,FALSE) -> David Santiago Medina Buitrago | H14: IZQUIERDA | I14: DERECHA | J14: DERECHA | K14: IZQUIERDA | L14: 1 | M14: 0 | Q14: Nicolas Navarro | R14: 38 | S14: 4 | V14: Luis Jorge Garcia Camargo | W14: 4 | X14: 7 | Z14: Maria Fernanda Tamayo Lopez | AA14: 16 | AB14: 6 | AD14: maria jose martinez villabona | AE14: 16 | AF14: 6
A15: 6 | B15: 2 | C15: 5 | D15: Luis Mario Ramirez Munoz | E15: Carlos Felipe Andrade Saenz | F15: =VLOOKUP(Tabla138[[#This Row],[ID_PARTIDO]],Original!$AT$1:$AY$46,4,FALSE) -> Fermin Alejandro Escalona Guillen | G15: =VLOOKUP(Tabla138[[#This Row],[ID_PARTIDO]],Original!$AT$1:$AY$46,5,FALSE) -> David Santiago Medina Buitrago | H15: IZQUIERDA | I15: DERECHA | J15: DERECHA | K15: IZQUIERDA | L15: 1 | M15: 0 | Q15: Nicolas Navarro | R15: 39 | S15: 6 | V15: Luis Jorge Garcia Camargo | W15: 32 | X15: 7 | Z15: Maria Fernanda Tamayo Lopez | AA15: 39 | AB15: 8 | AD15: Nicolas Navarro | AE15: 8 | AF15: 4
A16: 6 | B16: 2 | C16: 6 | D16: Luis Mario Ramirez Munoz | E16: Carlos Felipe Andrade Saenz | F16: =VLOOKUP(Tabla138[[#This Row],[ID_PARTIDO]],Original!$AT$1:$AY$46,4,FALSE) -> Fermin Alejandro Escalona Guillen | G16: =VLOOKUP(Tabla138[[#This Row],[ID_PARTIDO]],Original!$AT$1:$AY$46,5,FALSE) -> David Santiago Medina Buitrago | H16: IZQUIERDA | I16: DERECHA | J16: DERECHA | K16: IZQUIERDA | L16: 0 | M16: 1 | Q16: Rafael Andres Salcedo Valdivieso | R16: 4 | S16: 7 | V16: Maria Fernanda Tamayo Lopez | W16: 10 | X16: 6 | Z16: maria jose martinez villabona | AA16: 8 | AB16: 4 | AD16: Nicolas Navarro | AE16: 26 | AF16: 7
A17: 6 | B17: 2 | C17: 7 | D17: Luis Mario Ramirez Munoz | E17: Carlos Felipe Andrade Saenz | F17: =VLOOKUP(Tabla138[[#This Row],[ID_PARTIDO]],Original!$AT$1:$AY$46,4,FALSE) -> Fermin Alejandro Escalona Guillen | G17: =VLOOKUP(Tabla138[[#This Row],[ID_PARTIDO]],Original!$AT$1:$AY$46,5,FALSE) -> David Santiago Medina Buitrago | H17: IZQUIERDA | I17: DERECHA | J17: DERECHA | K17: IZQUIERDA | L17: 0 | M17: 1 | Q17: Rafael Andres Salcedo Valdivieso | R17: 28 | S17: 7 | V17: maria jose martinez villabona | W17: 39 | X17: 6 | Z17: maria jose martinez villabona | AA17: 10 | AB17: 6 | AD17: Nikol sofia avendaño | AE17: 10 | AF17: 6
A18: 6 | B18: 2 | C18: 8 | D18: Luis Mario Ramirez Munoz | E18: Carlos Felipe Andrade Saenz | F18: =VLOOKUP(Tabla138[[#This Row],[ID_PARTIDO]],Original!$AT$1:$AY$46,4,FALSE) -> Fermin Alejandro Escalona Guillen | G18: =VLOOKUP(Tabla138[[#This Row],[ID_PARTIDO]],Original!$AT$1:$AY$46,5,FALSE) -> David Santiago Medina Buitrago | H18: IZQUIERDA | I18: DERECHA | J18: DERECHA | K18: IZQUIERDA | L18: 1 | M18: 0 | Q18: Samuel Andrés Rodríguez Ulloa | R18: 8 | S18: 7 | V18: Nicolas Navarro | W18: 37 | X18: 4 | Z18: Nicole Lizarazo | AA18: 37 | AB18: 7 | AD18: Rafael Andres Salcedo Valdivieso | AE18: 36 | AF18: 7
A19: 6 | B19: 2 | C19: 9 | D19: Luis Mario Ramirez Munoz | E19: Carlos Felipe Andrade Saenz | F19: =VLOOKUP(Tabla138[[#This Row],[ID_PARTIDO]],Original!$AT$1:$AY$46,4,FALSE) -> Fermin Alejandro Escalona Guillen | G19: =VLOOKUP(Tabla138[[#This Row],[ID_PARTIDO]],Original!$AT$1:$AY$46,5,FALSE) -> David Santiago Medina Buitrago | H19: IZQUIERDA | I19: DERECHA | J19: DERECHA | K19: IZQUIERDA | L19: 0 | M19: 1 | Q19: Santiago Navarro Cuy | R19: 20 | S19: 5 | V19: Rafael Andres Salcedo Valdivieso | W19: 14 | X19: 7 | Z19: Nikol sofia avendano | AA19: 2 | AB19: 2 | AD19: Samuel Andrés Rodríguez Ulloa | AE19: 34 | AF19: 7
A20: 6 | B20: 2 | C20: 10 | D20: Luis Mario Ramirez Munoz | E20: Carlos Felipe Andrade Saenz | F20: =VLOOKUP(Tabla138[[#This Row],[ID_PARTIDO]],Original!$AT$1:$AY$46,4,FALSE) -> Fermin Alejandro Escalona Guillen | G20: =VLOOKUP(Tabla138[[#This Row],[ID_PARTIDO]],Original!$AT$1:$AY$46,5,FALSE) -> David Santiago Medina Buitrago | H20: IZQUIERDA | I20: DERECHA | J20: DERECHA | K20: IZQUIERDA | L20: 1 | M20: 0 | Q20: Santiago Navarro Cuy | R20: 34 | S20: 3 | V20: Samuel Andrés Rodríguez Ulloa | W20: 16 | X20: 7 | Z20: Nikol sofia avendaño | AA20: 34 | AB20: 7 | AD20: Santiago Gutiérrez de Piñeres Barbosa | AE20: 22 | AF20: 7
A21: 6 | B21: 2 | C21: 11 | D21: Luis Mario Ramirez Munoz | E21: Carlos Felipe Andrade Saenz | F21: =VLOOKUP(Tabla138[[#This Row],[ID_PARTIDO]],Original!$AT$1:$AY$46,4,FALSE) -> Fermin Alejandro Escalona Guillen | G21: =VLOOKUP(Tabla138[[#This Row],[ID_PARTIDO]],Original!$AT$1:$AY$46,5,FALSE) -> David Santiago Medina Buitrago | H21: IZQUIERDA | I21: DERECHA | J21: DERECHA | K21: IZQUIERDA | L21: 0 | M21: 1 | Q21: Santiago Peña Beltran | R21: 16 | S21: 7 | V21: Santiago Gutierrez de Pineres | W21: 2 | X21: 7 | Z21: Santiago Gutiérrez de Piñeres Barbosa | AA21: 18 | AB21: 7 | AD21: sara juliana solano boada | AE21: 42 | AF21: 2
A22: 6 | B22: 2 | C22: 12 | D22: Luis Mario Ramirez Munoz | E22: Carlos Felipe Andrade Saenz | F22: =VLOOKUP(Tabla138[[#This Row],[ID_PARTIDO]],Original!$AT$1:$AY$46,4,FALSE) -> Fermin Alejandro Escalona Guillen | G22: =VLOOKUP(Tabla138[[#This Row],[ID_PARTIDO]],Original!$AT$1:$AY$46,5,FALSE) -> David Santiago Medina Buitrago | H22: IZQUIERDA | I22: DERECHA | J22: DERECHA | K22: IZQUIERDA | L22: 1 | M22: 0 | Q22: Santiago Urrego Rodríguez | R22: 10 | S22: 6 | V22: Santiago Peña Beltran | W22: 12 | X22: 1 | Z22: Santiago Gutiérrez de Piñeres Barbosa | AA22: 38 | AB22: 7 | AD22: Sergio Andrés López Rodríguez | AE22: 12 | AF22: 7
A23: 8 | B23: 2 | C23: 1 | D23: Samuel Andrés Rodríguez Ulloa | E23: Sergio Andrés López Rodríguez | F23: maria jose martinez villabona | G23: =VLOOKUP(Tabla138[[#This Row],[ID_PARTIDO]],Original!$AT$1:$AY$46,5,FALSE) -> Nicolas Navarro | H23: DERECHA | I23: IZQUIERDA | J23: DERECHA | K23: IZQUIERDA | L23: 1 | M23: 0 | Q23: Santiago Urrego Rodríguez | R23: 12 | S23: 1 | V23: sara juliana solano boada | W23: 34 | X23: 3 | Z23: Santiago Navarro Cuy | AA23: 4 | AB23: 2 | AD23: Sergio Andrés López Rodríguez | AE23: 32 | AF23: 5
A24: 8 | B24: 2 | C24: 2 | D24: Samuel Andrés Rodríguez Ulloa | E24: Sergio Andrés López Rodríguez | F24: maria jose martinez villabona | G24: =VLOOKUP(Tabla138[[#This Row],[ID_PARTIDO]],Original!$AT$1:$AY$46,5,FALSE) -> Nicolas Navarro | H24: DERECHA | I24: IZQUIERDA | J24: DERECHA | K24: IZQUIERDA | L24: 1 | M24: 0 | Q24: Santiago Urrego Rodríguez | R24: 24 | S24: 4 | V24: sara juliana solano boada | W24: 38 | X24: 4 | Z24: sara juliana solano boada | AA24: 20 | AB24: 7 | AD24: Valentina Alejandra Lopez Romero | AE24: 28 | AF24: 2
A25: 8 | B25: 2 | C25: 3 | D25: Samuel Andrés Rodríguez Ulloa | E25: Sergio Andrés López Rodríguez | F25: maria jose martinez villabona | G25: =VLOOKUP(Tabla138[[#This Row],[ID_PARTIDO]],Original!$AT$1:$AY$46,5,FALSE) -> Nicolas Navarro | H25: DERECHA | I25: IZQUIERDA | J25: DERECHA | K25: IZQUIERDA | L25: 0 | M25: 1 | Q25: sara juliana solano boada | R25: 40 | S25: 4 | V25: Sergio Andrés López Rodríguez | W25: 8 | X25: 7 | Z25: Tomas Barrios Guevara | AA25: 26 | AB25: 7 | AD25: Valentina Jimenez Gomez | AE25: 2 | AF25: 2
A26: 8 | B26: 2 | C26: 4 | D26: Samuel Andrés Rodríguez Ulloa | E26: Sergio Andrés López Rodríguez | F26: maria jose martinez villabona | G26: =VLOOKUP(Tabla138[[#This Row],[ID_PARTIDO]],Original!$AT$1:$AY$46,5,FALSE) -> Nicolas Navarro | H26: DERECHA | I26: IZQUIERDA | J26: DERECHA | K26: IZQUIERDA | L26: 0 | M26: 1 | Q26: Sergio Andrés López Rodríguez | R26: 42 | S26: 7 | V26: Valentina Jimenez Gomez | W26: 22 | X26: 6 | Z26: Tomas Barrios Guevara | AA26: 36 | AB26: 7 | AD26: Valentina Jimenez Gomez | AE26: 24 | AF26: 7
A27: 8 | B27: 2 | C27: 5 | D27: Samuel Andrés Rodríguez Ulloa | E27: Sergio Andrés López Rodríguez | F27: maria jose martinez villabona | G27: =VLOOKUP(Tabla138[[#This Row],[ID_PARTIDO]],Original!$AT$1:$AY$46,5,FALSE) -> Nicolas Navarro | H27: DERECHA | I27: IZQUIERDA | J27: DERECHA | K27: IZQUIERDA | L27: 0 | M27: 1 | Q27: Total general | S27: 121 | V27: Total general | X27: 121 | Z27: Total general | AB27: 137 | AD27: (en blanco) | AE27: (en blanco)
A28: 8 | B28: 2 | C28: 6 | D28: Samuel Andrés Rodríguez Ulloa | E28: Sergio Andrés López Rodríguez | F28: maria jose martinez villabona | G28: =VLOOKUP(Tabla138[[#This Row],[ID_PARTIDO]],Original!$AT$1:$AY$46,5,FALSE) -> Nicolas Navarro | H28: DERECHA | I28: IZQUIERDA | J28: DERECHA | K28: IZQUIERDA | L28: 0 | M28: 1 | AD28: Total general | AF28: 137
A29: 8 | B29: 2 | C29: 7 | D29: Samuel Andrés Rodríguez Ulloa | E29: Sergio Andrés López Rodríguez | F29: maria jose martinez villabona | G29: =VLOOKUP(Tabla138[[#This Row],[ID_PARTIDO]],Original!$AT$1:$AY$46,5,FALSE) -> Nicolas Navarro | H29: DERECHA | I29: IZQUIERDA | J29: DERECHA | K29: IZQUIERDA | L29: 1 | M29: 0
A30: 8 | B30: 2 | C30: 8 | D30: Samuel Andrés Rodríguez Ulloa | E30: Sergio Andrés López Rodríguez | F30: maria jose martinez villabona | G30: =VLOOKUP(Tabla138[[#This Row],[ID_PARTIDO]],Original!$AT$1:$AY$46,5,FALSE) -> Nicolas Navarro | H30: DERECHA | I30: IZQUIERDA | J30: DERECHA | K30: IZQUIERDA | L30: 1 | M30: 0
A31: 8 | B31: 2 | C31: 9 | D31: Samuel Andrés Rodríguez Ulloa | E31: Sergio Andrés López Rodríguez | F31: maria jose martinez villabona | G31: =VLOOKUP(Tabla138[[#This Row],[ID_PARTIDO]],Original!$AT$1:$AY$46,5,FALSE) -> Nicolas Navarro | H31: DERECHA | I31: IZQUIERDA | J31: DERECHA | K31: IZQUIERDA | L31: 1 | M31: 0
A32: 8 | B32: 2 | C32: 10 | D32: Samuel Andrés Rodríguez Ulloa | E32: Sergio Andrés López Rodríguez | F32: maria jose martinez villabona | G32: =VLOOKUP(Tabla138[[#This Row],[ID_PARTIDO]],Original!$AT$1:$AY$46,5,FALSE) -> Nicolas Navarro | H32: DERECHA | I32: IZQUIERDA | J32: DERECHA | K32: IZQUIERDA | L32: 1 | M32: 0
A33: 8 | B33: 2 | C33: 11 | D33: Samuel Andrés Rodríguez Ulloa | E33: Sergio Andrés López Rodríguez | F33: maria jose martinez villabona | G33: =VLOOKUP(Tabla138[[#This Row],[ID_PARTIDO]],Original!$AT$1:$AY$46,5,FALSE) -> Nicolas Navarro | H33: DERECHA | I33: IZQUIERDA | J33: DERECHA | K33: IZQUIERDA | L33: 1 | M33: 0
A34: 4 | B34: 2 | C34: 1 | D34: =VLOOKUP(Tabla138[[#This Row],[ID_PARTIDO]],Original!$AT$1:$AY$46,2,FALSE) -> Rafael Andres Salcedo Valdivieso | E34: =VLOOKUP(Tabla138[[#This Row],[ID_PARTIDO]],Original!$AT$1:$AY$46,3,FALSE) -> Luis Jorge Garcia Camargo | F34: =VLOOKUP(Tabla138[[#This Row],[ID_PARTIDO]],Original!$AT$1:$AY$46,4,FALSE) -> Santiago Navarro Cuy | G34: =VLOOKUP(Tabla138[[#This Row],[ID_PARTIDO]],Original!$AT$1:$AY$46,5,FALSE) -> Juan Pablo Aponte Veloza | H34: DERECHA | I34: IZQUIERDA | J34: IZQUIERDA | K34: DERECHA | L34: 0 | M34: 1
A35: 4 | B35: 2 | C35: 2 | D35: =VLOOKUP(Tabla138[[#This Row],[ID_PARTIDO]],Original!$AT$1:$AY$46,2,FALSE) -> Rafael Andres Salcedo Valdivieso | E35: =VLOOKUP(Tabla138[[#This Row],[ID_PARTIDO]],Original!$AT$1:$AY$46,3,FALSE) -> Luis Jorge Garcia Camargo | F35: =VLOOKUP(Tabla138[[#This Row],[ID_PARTIDO]],Original!$AT$1:$AY$46,4,FALSE) -> Santiago Navarro Cuy | G35: =VLOOKUP(Tabla138[[#This Row],[ID_PARTIDO]],Original!$AT$1:$AY$46,5,FALSE) -> Juan Pablo Aponte Veloza | H35: DERECHA | I35: IZQUIERDA | J35: IZQUIERDA | K35: DERECHA | L35: 1 | M35: 0
A36: 4 | B36: 2 | C36: 3 | D36: =VLOOKUP(Tabla138[[#This Row],[ID_PARTIDO]],Original!$AT$1:$AY$46,2,FALSE) -> Rafael Andres Salcedo Valdivieso | E36: =VLOOKUP(Tabla138[[#This Row],[ID_PARTIDO]],Original!$AT$1:$AY$46,3,FALSE) -> Luis Jorge Garcia Camargo | F36: =VLOOKUP(Tabla138[[#This Row],[ID_PARTIDO]],Original!$AT$1:$AY$46,4,FALSE) -> Santiago Navarro Cuy | G36: =VLOOKUP(Tabla138[[#This Row],[ID_PARTIDO]],Original!$AT$1:$AY$46,5,FALSE) -> Juan Pablo Aponte Veloza | H36: DERECHA | I36: IZQUIERDA | J36: IZQUIERDA | K36: DERECHA | L36: 1 | M36: 0
A37: 4 | B37: 2 | C37: 4 | D37: =VLOOKUP(Tabla138[[#This Row],[ID_PARTIDO]],Original!$AT$1:$AY$46,2,FALSE) -> Rafael Andres Salcedo Valdivieso | E37: =VLOOKUP(Tabla138[[#This Row],[ID_PARTIDO]],Original!$AT$1:$AY$46,3,FALSE) -> Luis Jorge Garcia Camargo | F37: =VLOOKUP(Tabla138[[#This Row],[ID_PARTIDO]],Original!$AT$1:$AY$46,4,FALSE) -> Santiago Navarro Cuy | G37: =VLOOKUP(Tabla138[[#This Row],[ID_PARTIDO]],Original!$AT$1:$AY$46,5,FALSE) -> Juan Pablo Aponte Veloza | H37: DERECHA | I37: IZQUIERDA | J37: IZQUIERDA | K37: DERECHA | L37: 1 | M37: 0
A38: 4 | B38: 2 | C38: 5 | D38: =VLOOKUP(Tabla138[[#This Row],[ID_PARTIDO]],Original!$AT$1:$AY$46,2,FALSE) -> Rafael Andres Salcedo Valdivieso | E38: =VLOOKUP(Tabla138[[#This Row],[ID_PARTIDO]],Original!$AT$1:$AY$46,3,FALSE) -> Luis Jorge Garcia Camargo | F38: =VLOOKUP(Tabla138[[#This Row],[ID_PARTIDO]],Original!$AT$1:$AY$46,4,FALSE) -> Santiago Navarro Cuy | G38: =VLOOKUP(Tabla138[[#This Row],[ID_PARTIDO]],Original!$AT$1:$AY$46,5,FALSE) -> Juan Pablo Aponte Veloza | H38: DERECHA | I38: IZQUIERDA | J38: IZQUIERDA | K38: DERECHA | L38: 1 | M38: 0
A39: 4 | B39: 2 | C39: 6 | D39: =VLOOKUP(Tabla138[[#This Row],[ID_PARTIDO]],Original!$AT$1:$AY$46,2,FALSE) -> Rafael Andres Salcedo Valdivieso | E39: =VLOOKUP(Tabla138[[#This Row],[ID_PARTIDO]],Original!$AT$1:$AY$46,3,FALSE) -> Luis Jorge Garcia Camargo | F39: =VLOOKUP(Tabla138[[#This Row],[ID_PARTIDO]],Original!$AT$1:$AY$46,4,FALSE) -> Santiago Navarro Cuy | G39: =VLOOKUP(Tabla138[[#This Row],[ID_PARTIDO]],Original!$AT$1:$AY$46,5,FALSE) -> Juan Pablo Aponte Veloza | H39: DERECHA | I39: IZQUIERDA | J39: IZQUIERDA | K39: DERECHA | L39: 1 | M39: 0
A40: 4 | B40: 2 | C40: 7 | D40: =VLOOKUP(Tabla138[[#This Row],[ID_PARTIDO]],Original!$AT$1:$AY$46,2,FALSE) -> Rafael Andres Salcedo Valdivieso | E40: =VLOOKUP(Tabla138[[#This Row],[ID_PARTIDO]],Original!$AT$1:$AY$46,3,FALSE) -> Luis Jorge Garcia Camargo | F40: =VLOOKUP(Tabla138[[#This Row],[ID_PARTIDO]],Original!$AT$1:$AY$46,4,FALSE) -> Santiago Navarro Cuy | G40: =VLOOKUP(Tabla138[[#This Row],[ID_PARTIDO]],Original!$AT$1:$AY$46,5,FALSE) -> Juan Pablo Aponte Veloza | H40: DERECHA | I40: IZQUIERDA | J40: IZQUIERDA | K40: DERECHA | L40: 1 | M40: 0
...

Sheet CANCHA_2
A1: ID_PARTIDO | B1: CANCHA | C1: ID_PUNTO | D1: ID_JUGADOR_1_EQUIPO_1 | E1: ID_JUGADOR_2_EQUIPO_1 | F1: ID_JUGADOR_1_EQUIPO_2 | G1: ID_JUGADOR_2_EQUIPO_2 | H1: POSICION_JUGADOR_1_EQUIPO_1 | I1: POSICION_JUGADOR_2_EQUIPO_1 | J1: POSICION_JUGADOR_1_EQUIPO_2 | K1: POSICION_JUGADOR_2_EQUIPO_2 | L1: PUNTO_EQUIPO_1 | M1: PUNTO_EQUIPO_2
A2: 2 | B2: 2 | C2: 1 | D2: Luis Mario Ramirez Munoz | E2: Santiago Gutierrez de Pineres | F2: Nikol sofia avendano | G2: =VLOOKUP(Tabla13[[#This Row],[ID_PARTIDO]],Original!$AT$1:$AY$46,5,FALSE) -> Valentina Jimenez Gomez | H2: IZQUIERDA | I2: DERECHA | J2: IZQUIERDA | K2: DERECHA | L2: 1 | M2: 0
A3: 2 | B3: 2 | C3: 2 | D3: Luis Mario Ramirez Munoz | E3: Santiago Gutierrez de Pineres | F3: Nikol sofia avendano | G3: =VLOOKUP(Tabla13[[#This Row],[ID_PARTIDO]],Original!$AT$1:$AY$46,5,FALSE) -> Valentina Jimenez Gomez | H3: IZQUIERDA | I3: DERECHA | J3: IZQUIERDA | K3: DERECHA | L3: 1 | M3: 0
A4: 2 | B4: 2 | C4: 3 | D4: Luis Mario Ramirez Munoz | E4: Santiago Gutierrez de Pineres | F4: Nikol sofia avendano | G4: =VLOOKUP(Tabla13[[#This Row],[ID_PARTIDO]],Original!$AT$1:$AY$46,5,FALSE) -> Valentina Jimenez Gomez | H4: IZQUIERDA | I4: DERECHA | J4: IZQUIERDA | K4: DERECHA | L4: 1 | M4: 0
A5: 2 | B5: 2 | C5: 4 | D5: Luis Mario Ramirez Munoz | E5: Santiago Gutierrez de Pineres | F5: Nikol sofia avendano | G5: =VLOOKUP(Tabla13[[#This Row],[ID_PARTIDO]],Original!$AT$1:$AY$46,5,FALSE) -> Valentina Jimenez Gomez | H5: IZQUIERDA | I5: DERECHA | J5: IZQUIERDA | K5: DERECHA | L5: 0 | M5: 1
A6: 2 | B6: 2 | C6: 5 | D6: Luis Mario Ramirez Munoz | E6: Santiago Gutierrez de Pineres | F6: Nikol sofia avendano | G6: =VLOOKUP(Tabla13[[#This Row],[ID_PARTIDO]],Original!$AT$1:$AY$46,5,FALSE) -> Valentina Jimenez Gomez | H6: IZQUIERDA | I6: DERECHA | J6: IZQUIERDA | K6: DERECHA | L6: 1 | M6: 0
A7: 2 | B7: 2 | C7: 6 | D7: Luis Mario Ramirez Munoz | E7: Santiago Gutierrez de Pineres | F7: Nikol sofia avendano | G7: =VLOOKUP(Tabla13[[#This Row],[ID_PARTIDO]],Original!$AT$1:$AY$46,5,FALSE) -> Valentina Jimenez Gomez | H7: IZQUIERDA | I7: DERECHA | J7: IZQUIERDA | K7: DERECHA | L7: 0 | M7: 1
A8: 2 | B8: 2 | C8: 7 | D8: Luis Mario Ramirez Munoz | E8: Santiago Gutierrez de Pineres | F8: Nikol sofia avendano | G8: =VLOOKUP(Tabla13[[#This Row],[ID_PARTIDO]],Original!$AT$1:$AY$46,5,FALSE) -> Valentina Jimenez Gomez | H8: IZQUIERDA | I8: DERECHA | J8: IZQUIERDA | K8: DERECHA | L8: 1 | M8: 0
A9: 2 | B9: 2 | C9: 8 | D9: Luis Mario Ramirez Munoz | E9: Santiago Gutierrez de Pineres | F9: Nikol sofia avendano | G9: =VLOOKUP(Tabla13[[#This Row],[ID_PARTIDO]],Original!$AT$1:$AY$46,5,FALSE) -> Valentina Jimenez Gomez | H9: IZQUIERDA | I9: DERECHA | J9: IZQUIERDA | K9: DERECHA | L9: 1 | M9: 0
A10: 2 | B10: 2 | C10: 9 | D10: Luis Mario Ramirez Munoz | E10: Santiago Gutierrez de Pineres | F10: Nikol sofia avendano | G10: =VLOOKUP(Tabla13[[#This Row],[ID_PARTIDO]],Original!$AT$1:$AY$46,5,FALSE) -> Valentina Jimenez Gomez | H10: IZQUIERDA | I10: DERECHA | J10: IZQUIERDA | K10: DERECHA | L10: 1 | M10: 0
A11: 6 | B11: 2 | C11: 1 | D11: Luis Mario Ramirez Munoz | E11: Carlos Felipe Andrade Saenz | F11: =VLOOKUP(Tabla13[[#This Row],[ID_PARTIDO]],Original!$AT$1:$AY$46,4,FALSE) -> Fermin Alejandro Escalona Guillen | G11: =VLOOKUP(Tabla13[[#This Row],[ID_PARTIDO]],Original!$AT$1:$AY$46,5,FALSE) -> David Santiago Medina Buitrago | H11: IZQUIERDA | I11: DERECHA | J11: DERECHA | K11: IZQUIERDA | L11: 0 | M11: 1
A12: 6 | B12: 2 | C12: 2 | D12: Luis Mario Ramirez Munoz | E12: Carlos Felipe Andrade Saenz | F12: =VLOOKUP(Tabla13[[#This Row],[ID_PARTIDO]],Original!$AT$1:$AY$46,4,FALSE) -> Fermin Alejandro Escalona Guillen | G12: =VLOOKUP(Tabla13[[#This Row],[ID_PARTIDO]],Original!$AT$1:$AY$46,5,FALSE) -> David Santiago Medina Buitrago | H12: IZQUIERDA | I12: DERECHA | J12: DERECHA | K12: IZQUIERDA | L12: 1 | M12: 0
A13: 6 | B13: 2 | C13: 3 | D13: Luis Mario Ramirez Munoz | E13: Carlos Felipe Andrade Saenz | F13: =VLOOKUP(Tabla13[[#This Row],[ID_PARTIDO]],Original!$AT$1:$AY$46,4,FALSE) -> Fermin Alejandro Escalona Guillen | G13: =VLOOKUP(Tabla13[[#This Row],[ID_PARTIDO]],Original!$AT$1:$AY$46,5,FALSE) -> David Santiago Medina Buitrago | H13: IZQUIERDA | I13: DERECHA | J13: DERECHA | K13: IZQUIERDA | L13: 0 | M13: 1
A14: 6 | B14: 2 | C14: 4 | D14: Luis Mario Ramirez Munoz | E14: Carlos Felipe Andrade Saenz | F14: =VLOOKUP(Tabla13[[#This Row],[ID_PARTIDO]],Original!$AT$1:$AY$46,4,FALSE) -> Fermin Alejandro Escalona Guillen | G14: =VLOOKUP(Tabla13[[#This Row],[ID_PARTIDO]],Original!$AT$1:$AY$46,5,FALSE) -> David Santiago Medina Buitrago | H14: IZQUIERDA | I14: DERECHA | J14: DERECHA | K14: IZQUIERDA | L14: 1 | M14: 0
A15: 6 | B15: 2 | C15: 5 | D15: Luis Mario Ramirez Munoz | E15: Carlos Felipe Andrade Saenz | F15: =VLOOKUP(Tabla13[[#This Row],[ID_PARTIDO]],Original!$AT$1:$AY$46,4,FALSE) -> Fermin Alejandro Escalona Guillen | G15: =VLOOKUP(Tabla13[[#This Row],[ID_PARTIDO]],Original!$AT$1:$AY$46,5,FALSE) -> David Santiago Medina Buitrago | H15: IZQUIERDA | I15: DERECHA | J15: DERECHA | K15: IZQUIERDA | L15: 1 | M15: 0
A16: 6 | B16: 2 | C16: 6 | D16: Luis Mario Ramirez Munoz | E16: Carlos Felipe Andrade Saenz | F16: =VLOOKUP(Tabla13[[#This Row],[ID_PARTIDO]],Original!$AT$1:$AY$46,4,FALSE) -> Fermin Alejandro Escalona Guillen | G16: =VLOOKUP(Tabla13[[#This Row],[ID_PARTIDO]],Original!$AT$1:$AY$46,5,FALSE) -> David Santiago Medina Buitrago | H16: IZQUIERDA | I16: DERECHA | J16: DERECHA | K16: IZQUIERDA | L16: 0 | M16: 1
A17: 6 | B17: 2 | C17: 7 | D17: Luis Mario Ramirez Munoz | E17: Carlos Felipe Andrade Saenz | F17: =VLOOKUP(Tabla13[[#This Row],[ID_PARTIDO]],Original!$AT$1:$AY$46,4,FALSE) -> Fermin Alejandro Escalona Guillen | G17: =VLOOKUP(Tabla13[[#This Row],[ID_PARTIDO]],Original!$AT$1:$AY$46,5,FALSE) -> David Santiago Medina Buitrago | H17: IZQUIERDA | I17: DERECHA | J17: DERECHA | K17: IZQUIERDA | L17: 0 | M17: 1
A18: 6 | B18: 2 | C18: 8 | D18: Luis Mario Ramirez Munoz | E18: Carlos Felipe Andrade Saenz | F18: =VLOOKUP(Tabla13[[#This Row],[ID_PARTIDO]],Original!$AT$1:$AY$46,4,FALSE) -> Fermin Alejandro Escalona Guillen | G18: =VLOOKUP(Tabla13[[#This Row],[ID_PARTIDO]],Original!$AT$1:$AY$46,5,FALSE) -> David Santiago Medina Buitrago | H18: IZQUIERDA | I18: DERECHA | J18: DERECHA | K18: IZQUIERDA | L18: 1 | M18: 0
A19: 6 | B19: 2 | C19: 9 | D19: Luis Mario Ramirez Munoz | E19: Carlos Felipe Andrade Saenz | F19: =VLOOKUP(Tabla13[[#This Row],[ID_PARTIDO]],Original!$AT$1:$AY$46,4,FALSE) -> Fermin Alejandro Escalona Guillen | G19: =VLOOKUP(Tabla13[[#This Row],[ID_PARTIDO]],Original!$AT$1:$AY$46,5,FALSE) -> David Santiago Medina Buitrago | H19: IZQUIERDA | I19: DERECHA | J19: DERECHA | K19: IZQUIERDA | L19: 0 | M19: 1
A20: 6 | B20: 2 | C20: 10 | D20: Luis Mario Ramirez Munoz | E20: Carlos Felipe Andrade Saenz | F20: =VLOOKUP(Tabla13[[#This Row],[ID_PARTIDO]],Original!$AT$1:$AY$46,4,FALSE) -> Fermin Alejandro Escalona Guillen | G20: =VLOOKUP(Tabla13[[#This Row],[ID_PARTIDO]],Original!$AT$1:$AY$46,5,FALSE) -> David Santiago Medina Buitrago | H20: IZQUIERDA | I20: DERECHA | J20: DERECHA | K20: IZQUIERDA | L20: 1 | M20: 0
A21: 6 | B21: 2 | C21: 11 | D21: Luis Mario Ramirez Munoz | E21: Carlos Felipe Andrade Saenz | F21: =VLOOKUP(Tabla13[[#This Row],[ID_PARTIDO]],Original!$AT$1:$AY$46,4,FALSE) -> Fermin Alejandro Escalona Guillen | G21: =VLOOKUP(Tabla13[[#This Row],[ID_PARTIDO]],Original!$AT$1:$AY$46,5,FALSE) -> David Santiago Medina Buitrago | H21: IZQUIERDA | I21: DERECHA | J21: DERECHA | K21: IZQUIERDA | L21: 0 | M21: 1
A22: 6 | B22: 2 | C22: 12 | D22: Luis Mario Ramirez Munoz | E22: Carlos Felipe Andrade Saenz | F22: =VLOOKUP(Tabla13[[#This Row],[ID_PARTIDO]],Original!$AT$1:$AY$46,4,FALSE) -> Fermin Alejandro Escalona Guillen | G22: =VLOOKUP(Tabla13[[#This Row],[ID_PARTIDO]],Original!$AT$1:$AY$46,5,FALSE) -> David Santiago Medina Buitrago | H22: IZQUIERDA | I22: DERECHA | J22: DERECHA | K22: IZQUIERDA | L22: 1 | M22: 0
A23: 8 | B23: 2 | C23: 1 | D23: Samuel Andrés Rodríguez Ulloa | E23: Sergio Andrés López Rodríguez | F23: maria jose martinez villabona | G23: =VLOOKUP(Tabla13[[#This Row],[ID_PARTIDO]],Original!$AT$1:$AY$46,5,FALSE) -> Nicolas Navarro | H23: DERECHA | I23: IZQUIERDA | J23: DERECHA | K23: IZQUIERDA | L23: 1 | M23: 0
A24: 8 | B24: 2 | C24: 2 | D24: Samuel Andrés Rodríguez Ulloa | E24: Sergio Andrés López Rodríguez | F24: maria jose martinez villabona | G24: =VLOOKUP(Tabla13[[#This Row],[ID_PARTIDO]],Original!$AT$1:$AY$46,5,FALSE) -> Nicolas Navarro | H24: DERECHA | I24: IZQUIERDA | J24: DERECHA | K24: IZQUIERDA | L24: 1 | M24: 0
A25: 8 | B25: 2 | C25: 3 | D25: Samuel Andrés Rodríguez Ulloa | E25: Sergio Andrés López Rodríguez | F25: maria jose martinez villabona | G25: =VLOOKUP(Tabla13[[#This Row],[ID_PARTIDO]],Original!$AT$1:$AY$46,5,FALSE) -> Nicolas Navarro | H25: DERECHA | I25: IZQUIERDA | J25: DERECHA | K25: IZQUIERDA | L25: 0 | M25: 1
A26: 8 | B26: 2 | C26: 4 | D26: Samuel Andrés Rodríguez Ulloa | E26: Sergio Andrés López Rodríguez | F26: maria jose martinez villabona | G26: =VLOOKUP(Tabla13[[#This Row],[ID_PARTIDO]],Original!$AT$1:$AY$46,5,FALSE) -> Nicolas Navarro | H26: DERECHA | I26: IZQUIERDA | J26: DERECHA | K26: IZQUIERDA | L26: 0 | M26: 1
A27: 8 | B27: 2 | C27: 5 | D27: Samuel Andrés Rodríguez Ulloa | E27: Sergio Andrés López Rodríguez | F27: maria jose martinez villabona | G27: =VLOOKUP(Tabla13[[#This Row],[ID_PARTIDO]],Original!$AT$1:$AY$46,5,FALSE) -> Nicolas Navarro | H27: DERECHA | I27: IZQUIERDA | J27: DERECHA | K27: IZQUIERDA | L27: 0 | M27: 1
A28: 8 | B28: 2 | C28: 6 | D28: Samuel Andrés Rodríguez Ulloa | E28: Sergio Andrés López Rodríguez | F28: maria jose martinez villabona | G28: =VLOOKUP(Tabla13[[#This Row],[ID_PARTIDO]],Original!$AT$1:$AY$46,5,FALSE) -> Nicolas Navarro | H28: DERECHA | I28: IZQUIERDA | J28: DERECHA | K28: IZQUIERDA | L28: 0 | M28: 1
A29: 8 | B29: 2 | C29: 7 | D29: Samuel Andrés Rodríguez Ulloa | E29: Sergio Andrés López Rodríguez | F29: maria jose martinez villabona | G29: =VLOOKUP(Tabla13[[#This Row],[ID_PARTIDO]],Original!$AT$1:$AY$46,5,FALSE) -> Nicolas Navarro | H29: DERECHA | I29: IZQUIERDA | J29: DERECHA | K29: IZQUIERDA | L29: 1 | M29: 0
A30: 8 | B30: 2 | C30: 8 | D30: Samuel Andrés Rodríguez Ulloa | E30: Sergio Andrés López Rodríguez | F30: maria jose martinez villabona | G30: =VLOOKUP(Tabla13[[#This Row],[ID_PARTIDO]],Original!$AT$1:$AY$46,5,FALSE) -> Nicolas Navarro | H30: DERECHA | I30: IZQUIERDA | J30: DERECHA | K30: IZQUIERDA | L30: 1 | M30: 0
A31: 8 | B31: 2 | C31: 9 | D31: Samuel Andrés Rodríguez Ulloa | E31: Sergio Andrés López Rodríguez | F31: maria jose martinez villabona | G31: =VLOOKUP(Tabla13[[#This Row],[ID_PARTIDO]],Original!$AT$1:$AY$46,5,FALSE) -> Nicolas Navarro | H31: DERECHA | I31: IZQUIERDA | J31: DERECHA | K31: IZQUIERDA | L31: 1 | M31: 0
A32: 8 | B32: 2 | C32: 10 | D32: Samuel Andrés Rodríguez Ulloa | E32: Sergio Andrés López Rodríguez | F32: maria jose martinez villabona | G32: =VLOOKUP(Tabla13[[#This Row],[ID_PARTIDO]],Original!$AT$1:$AY$46,5,FALSE) -> Nicolas Navarro | H32: DERECHA | I32: IZQUIERDA | J32: DERECHA | K32: IZQUIERDA | L32: 1 | M32: 0
A33: 8 | B33: 2 | C33: 11 | D33: Samuel Andrés Rodríguez Ulloa | E33: Sergio Andrés López Rodríguez | F33: maria jose martinez villabona | G33: =VLOOKUP(Tabla13[[#This Row],[ID_PARTIDO]],Original!$AT$1:$AY$46,5,FALSE) -> Nicolas Navarro | H33: DERECHA | I33: IZQUIERDA | J33: DERECHA | K33: IZQUIERDA | L33: 1 | M33: 0
A34: 4 | B34: 2 | C34: 1 | D34: =VLOOKUP(Tabla13[[#This Row],[ID_PARTIDO]],Original!$AT$1:$AY$46,2,FALSE) -> Rafael Andres Salcedo Valdivieso | E34: =VLOOKUP(Tabla13[[#This Row],[ID_PARTIDO]],Original!$AT$1:$AY$46,3,FALSE) -> Luis Jorge Garcia Camargo | F34: =VLOOKUP(Tabla13[[#This Row],[ID_PARTIDO]],Original!$AT$1:$AY$46,4,FALSE) -> Santiago Navarro Cuy | G34: =VLOOKUP(Tabla13[[#This Row],[ID_PARTIDO]],Original!$AT$1:$AY$46,5,FALSE) -> Juan Pablo Aponte Veloza | H34: DERECHA | I34: IZQUIERDA | J34: IZQUIERDA | K34: DERECHA | L34: 0 | M34: 1
A35: 4 | B35: 2 | C35: 2 | D35: =VLOOKUP(Tabla13[[#This Row],[ID_PARTIDO]],Original!$AT$1:$AY$46,2,FALSE) -> Rafael Andres Salcedo Valdivieso | E35: =VLOOKUP(Tabla13[[#This Row],[ID_PARTIDO]],Original!$AT$1:$AY$46,3,FALSE) -> Luis Jorge Garcia Camargo | F35: =VLOOKUP(Tabla13[[#This Row],[ID_PARTIDO]],Original!$AT$1:$AY$46,4,FALSE) -> Santiago Navarro Cuy | G35: =VLOOKUP(Tabla13[[#This Row],[ID_PARTIDO]],Original!$AT$1:$AY$46,5,FALSE) -> Juan Pablo Aponte Veloza | H35: DERECHA | I35: IZQUIERDA | J35: IZQUIERDA | K35: DERECHA | L35: 1 | M35: 0
A36: 4 | B36: 2 | C36: 3 | D36: =VLOOKUP(Tabla13[[#This Row],[ID_PARTIDO]],Original!$AT$1:$AY$46,2,FALSE) -> Rafael Andres Salcedo Valdivieso | E36: =VLOOKUP(Tabla13[[#This Row],[ID_PARTIDO]],Original!$AT$1:$AY$46,3,FALSE) -> Luis Jorge Garcia Camargo | F36: =VLOOKUP(Tabla13[[#This Row],[ID_PARTIDO]],Original!$AT$1:$AY$46,4,FALSE) -> Santiago Navarro Cuy | G36: =VLOOKUP(Tabla13[[#This Row],[ID_PARTIDO]],Original!$AT$1:$AY$46,5,FALSE) -> Juan Pablo Aponte Veloza | H36: DERECHA | I36: IZQUIERDA | J36: IZQUIERDA | K36: DERECHA | L36: 1 | M36: 0
A37: 4 | B37: 2 | C37: 4 | D37: =VLOOKUP(Tabla13[[#This Row],[ID_PARTIDO]],Original!$AT$1:$AY$46,2,FALSE) -> Rafael Andres Salcedo Valdivieso | E37: =VLOOKUP(Tabla13[[#This Row],[ID_PARTIDO]],Original!$AT$1:$AY$46,3,FALSE) -> Luis Jorge Garcia Camargo | F37: =VLOOKUP(Tabla13[[#This Row],[ID_PARTIDO]],Original!$AT$1:$AY$46,4,FALSE) -> Santiago Navarro Cuy | G37: =VLOOKUP(Tabla13[[#This Row],[ID_PARTIDO]],Original!$AT$1:$AY$46,5,FALSE) -> Juan Pablo Aponte Veloza | H37: DERECHA | I37: IZQUIERDA | J37: IZQUIERDA | K37: DERECHA | L37: 1 | M37: 0
A38: 4 | B38: 2 | C38: 5 | D38: =VLOOKUP(Tabla13[[#This Row],[ID_PARTIDO]],Original!$AT$1:$AY$46,2,FALSE) -> Rafael Andres Salcedo Valdivieso | E38: =VLOOKUP(Tabla13[[#This Row],[ID_PARTIDO]],Original!$AT$1:$AY$46,3,FALSE) -> Luis Jorge Garcia Camargo | F38: =VLOOKUP(Tabla13[[#This Row],[ID_PARTIDO]],Original!$AT$1:$AY$46,4,FALSE) -> Santiago Navarro Cuy | G38: =VLOOKUP(Tabla13[[#This Row],[ID_PARTIDO]],Original!$AT$1:$AY$46,5,FALSE) -> Juan Pablo Aponte Veloza | H38: DERECHA | I38: IZQUIERDA | J38: IZQUIERDA | K38: DERECHA | L38: 1 | M38: 0
A39: 4 | B39: 2 | C39: 6 | D39: =VLOOKUP(Tabla13[[#This Row],[ID_PARTIDO]],Original!$AT$1:$AY$46,2,FALSE) -> Rafael Andres Salcedo Valdivieso | E39: =VLOOKUP(Tabla13[[#This Row],[ID_PARTIDO]],Original!$AT$1:$AY$46,3,FALSE) -> Luis Jorge Garcia Camargo | F39: =VLOOKUP(Tabla13[[#This Row],[ID_PARTIDO]],Original!$AT$1:$AY$46,4,FALSE) -> Santiago Navarro Cuy | G39: =VLOOKUP(Tabla13[[#This Row],[ID_PARTIDO]],Original!$AT$1:$AY$46,5,FALSE) -> Juan Pablo Aponte Veloza | H39: DERECHA | I39: IZQUIERDA | J39: IZQUIERDA | K39: DERECHA | L39: 1 | M39: 0
A40: 4 | B40: 2 | C40: 7 | D40: =VLOOKUP(Tabla13[[#This Row],[ID_PARTIDO]],Original!$AT$1:$AY$46,2,FALSE) -> Rafael Andres Salcedo Valdivieso | E40: =VLOOKUP(Tabla13[[#This Row],[ID_PARTIDO]],Original!$AT$1:$AY$46,3,FALSE) -> Luis Jorge Garcia Camargo | F40: =VLOOKUP(Tabla13[[#This Row],[ID_PARTIDO]],Original!$AT$1:$AY$46,4,FALSE) -> Santiago Navarro Cuy | G40: =VLOOKUP(Tabla13[[#This Row],[ID_PARTIDO]],Original!$AT$1:$AY$46,5,FALSE) -> Juan Pablo Aponte Veloza | H40: DERECHA | I40: IZQUIERDA | J40: IZQUIERDA | K40: DERECHA | L40: 1 | M40: 0
...

Sheet Hoja2

Sheet CANCHA_1
A1: ID_PARTIDO | B1: CANCHA | C1: ID_PUNTO | D1: ID_JUGADOR_1_EQUIPO_1 | E1: ID_JUGADOR_2_EQUIPO_1 | F1: ID_JUGADOR_1_EQUIPO_2 | G1: ID_JUGADOR_2_EQUIPO_2 | H1: POSICION_JUGADOR_1_EQUIPO_1 | I1: POSICION_JUGADOR_2_EQUIPO_1 | J1: POSICION_JUGADOR_1_EQUIPO_2 | K1: POSICION_JUGADOR_2_EQUIPO_2 | L1: PUNTO_EQUIPO_1 | M1: PUNTO_EQUIPO_2
A2: 27 | B2: 1 | C2: 1 | D2: =VLOOKUP(Tabla1[[#This Row],[ID_PARTIDO]],Original!$AT$1:$AY$46,2,FALSE) -> Nicole Lizarazo | E2: =VLOOKUP(Tabla1[[#This Row],[ID_PARTIDO]],Original!$AT$1:$AY$46,3,FALSE) -> Valentina Alejandra Lopez Romero | F2: =VLOOKUP(Tabla1[[#This Row],[ID_PARTIDO]],Original!$AT$1:$AY$46,4,FALSE) -> Luis Jorge Garcia Camargo | G2: =VLOOKUP(Tabla1[[#This Row],[ID_PARTIDO]],Original!$AT$1:$AY$46,5,FALSE) -> Nikol sofia avendaño | H2: IZQUIERDA | I2: DERECHA | J2: IZQUIERDA | K2: DERECHA | L2: 1 | M2: 0
A3: 27 | B3: 1 | C3: 2 | D3: =VLOOKUP(Tabla1[[#This Row],[ID_PARTIDO]],Original!$AT$1:$AY$46,2,FALSE) -> Nicole Lizarazo | E3: =VLOOKUP(Tabla1[[#This Row],[ID_PARTIDO]],Original!$AT$1:$AY$46,3,FALSE) -> Valentina Alejandra Lopez Romero | F3: =VLOOKUP(Tabla1[[#This Row],[ID_PARTIDO]],Original!$AT$1:$AY$46,4,FALSE) -> Luis Jorge Garcia Camargo | G3: =VLOOKUP(Tabla1[[#This Row],[ID_PARTIDO]],Original!$AT$1:$AY$46,5,FALSE) -> Nikol sofia avendaño | H3: IZQUIERDA | I3: DERECHA | J3: IZQUIERDA | K3: DERECHA | L3: 0 | M3: 1
A4: 27 | B4: 1 | C4: 3 | D4: =VLOOKUP(Tabla1[[#This Row],[ID_PARTIDO]],Original!$AT$1:$AY$46,2,FALSE) -> Nicole Lizarazo | E4: =VLOOKUP(Tabla1[[#This Row],[ID_PARTIDO]],Original!$AT$1:$AY$46,3,FALSE) -> Valentina Alejandra Lopez Romero | F4: =VLOOKUP(Tabla1[[#This Row],[ID_PARTIDO]],Original!$AT$1:$AY$46,4,FALSE) -> Luis Jorge Garcia Camargo | G4: =VLOOKUP(Tabla1[[#This Row],[ID_PARTIDO]],Original!$AT$1:$AY$46,5,FALSE) -> Nikol sofia avendaño | H4: IZQUIERDA | I4: DERECHA | J4: IZQUIERDA | K4: DERECHA | L4: 0 | M4: 1
A5: 27 | B5: 1 | C5: 4 | D5: =VLOOKUP(Tabla1[[#This Row],[ID_PARTIDO]],Original!$AT$1:$AY$46,2,FALSE) -> Nicole Lizarazo | E5: =VLOOKUP(Tabla1[[#This Row],[ID_PARTIDO]],Original!$AT$1:$AY$46,3,FALSE) -> Valentina Alejandra Lopez Romero | F5: =VLOOKUP(Tabla1[[#This Row],[ID_PARTIDO]],Original!$AT$1:$AY$46,4,FALSE) -> Luis Jorge Garcia Camargo | G5: =VLOOKUP(Tabla1[[#This Row],[ID_PARTIDO]],Original!$AT$1:$AY$46,5,FALSE) -> Nikol sofia avendaño | H5: IZQUIERDA | I5: DERECHA | J5: IZQUIERDA | K5: DERECHA | L5: 1 | M5: 0
A6: 27 | B6: 1 | C6: 5 | D6: =VLOOKUP(Tabla1[[#This Row],[ID_PARTIDO]],Original!$AT$1:$AY$46,2,FALSE) -> Nicole Lizarazo | E6: =VLOOKUP(Tabla1[[#This Row],[ID_PARTIDO]],Original!$AT$1:$AY$46,3,FALSE) -> Valentina Alejandra Lopez Romero | F6: =VLOOKUP(Tabla1[[#This Row],[ID_PARTIDO]],Original!$AT$1:$AY$46,4,FALSE) -> Luis Jorge Garcia Camargo | G6: =VLOOKUP(Tabla1[[#This Row],[ID_PARTIDO]],Original!$AT$1:$AY$46,5,FALSE) -> Nikol sofia avendaño | H6: IZQUIERDA | I6: DERECHA | J6: IZQUIERDA | K6: DERECHA | L6: 0 | M6: 1
A7: 27 | B7: 1 | C7: 6 | D7: =VLOOKUP(Tabla1[[#This Row],[ID_PARTIDO]],Original!$AT$1:$AY$46,2,FALSE) -> Nicole Lizarazo | E7: =VLOOKUP(Tabla1[[#This Row],[ID_PARTIDO]],Original!$AT$1:$AY$46,3,FALSE) -> Valentina Alejandra Lopez Romero | F7: =VLOOKUP(Tabla1[[#This Row],[ID_PARTIDO]],Original!$AT$1:$AY$46,4,FALSE) -> Luis Jorge Garcia Camargo | G7: =VLOOKUP(Tabla1[[#This Row],[ID_PARTIDO]],Original!$AT$1:$AY$46,5,FALSE) -> Nikol sofia avendaño | H7: IZQUIERDA | I7: DERECHA | J7: IZQUIERDA | K7: DERECHA | L7: 1 | M7: 0
A8: 27 | B8: 1 | C8: 7 | D8: =VLOOKUP(Tabla1[[#This Row],[ID_PARTIDO]],Original!$AT$1:$AY$46,2,FALSE) -> Nicole Lizarazo | E8: =VLOOKUP(Tabla1[[#This Row],[ID_PARTIDO]],Original!$AT$1:$AY$46,3,FALSE) -> Valentina Alejandra Lopez Romero | F8: =VLOOKUP(Tabla1[[#This Row],[ID_PARTIDO]],Original!$AT$1:$AY$46,4,FALSE) -> Luis Jorge Garcia Camargo | G8: =VLOOKUP(Tabla1[[#This Row],[ID_PARTIDO]],Original!$AT$1:$AY$46,5,FALSE) -> Nikol sofia avendaño | H8: IZQUIERDA | I8: DERECHA | J8: IZQUIERDA | K8: DERECHA | L8: 0 | M8: 1
A9: 27 | B9: 1 | C9: 8 | D9: =VLOOKUP(Tabla1[[#This Row],[ID_PARTIDO]],Original!$AT$1:$AY$46,2,FALSE) -> Nicole Lizarazo | E9: =VLOOKUP(Tabla1[[#This Row],[ID_PARTIDO]],Original!$AT$1:$AY$46,3,FALSE) -> Valentina Alejandra Lopez Romero | F9: =VLOOKUP(Tabla1[[#This Row],[ID_PARTIDO]],Original!$AT$1:$AY$46,4,FALSE) -> Luis Jorge Garcia Camargo | G9: =VLOOKUP(Tabla1[[#This Row],[ID_PARTIDO]],Original!$AT$1:$AY$46,5,FALSE) -> Nikol sofia avendaño | H9: IZQUIERDA | I9: DERECHA | J9: IZQUIERDA | K9: DERECHA | L9: 1 | M9: 0
A10: 27 | B10: 1 | C10: 9 | D10: =VLOOKUP(Tabla1[[#This Row],[ID_PARTIDO]],Original!$AT$1:$AY$46,2,FALSE) -> Nicole Lizarazo | E10: =VLOOKUP(Tabla1[[#This Row],[ID_PARTIDO]],Original!$AT$1:$AY$46,3,FALSE) -> Valentina Alejandra Lopez Romero | F10: =VLOOKUP(Tabla1[[#This Row],[ID_PARTIDO]],Original!$AT$1:$AY$46,4,FALSE) -> Luis Jorge Garcia Camargo | G10: =VLOOKUP(Tabla1[[#This Row],[ID_PARTIDO]],Original!$AT$1:$AY$46,5,FALSE) -> Nikol sofia avendaño | H10: IZQUIERDA | I10: DERECHA | J10: IZQUIERDA | K10: DERECHA | L10: 0 | M10: 1
A11: 27 | B11: 1 | C11: 10 | D11: =VLOOKUP(Tabla1[[#This Row],[ID_PARTIDO]],Original!$AT$1:$AY$46,2,FALSE) -> Nicole Lizarazo | E11: =VLOOKUP(Tabla1[[#This Row],[ID_PARTIDO]],Original!$AT$1:$AY$46,3,FALSE) -> Valentina Alejandra Lopez Romero | F11: =VLOOKUP(Tabla1[[#This Row],[ID_PARTIDO]],Original!$AT$1:$AY$46,4,FALSE) -> Luis Jorge Garcia Camargo | G11: =VLOOKUP(Tabla1[[#This Row],[ID_PARTIDO]],Original!$AT$1:$AY$46,5,FALSE) -> Nikol sofia avendaño | H11: IZQUIERDA | I11: DERECHA | J11: IZQUIERDA | K11: DERECHA | L11: 1 | M11: 0
A12: 27 | B12: 1 | C12: 11 | D12: =VLOOKUP(Tabla1[[#This Row],[ID_PARTIDO]],Original!$AT$1:$AY$46,2,FALSE) -> Nicole Lizarazo | E12: =VLOOKUP(Tabla1[[#This Row],[ID_PARTIDO]],Original!$AT$1:$AY$46,3,FALSE) -> Valentina Alejandra Lopez Romero | F12: =VLOOKUP(Tabla1[[#This Row],[ID_PARTIDO]],Original!$AT$1:$AY$46,4,FALSE) -> Luis Jorge Garcia Camargo | G12: =VLOOKUP(Tabla1[[#This Row],[ID_PARTIDO]],Original!$AT$1:$AY$46,5,FALSE) -> Nikol sofia avendaño | H12: IZQUIERDA | I12: DERECHA | J12: IZQUIERDA | K12: DERECHA | L12: 1 | M12: 0
A13: 27 | B13: 1 | C13: 12 | D13: =VLOOKUP(Tabla1[[#This Row],[ID_PARTIDO]],Original!$AT$1:$AY$46,2,FALSE) -> Nicole Lizarazo | E13: =VLOOKUP(Tabla1[[#This Row],[ID_PARTIDO]],Original!$AT$1:$AY$46,3,FALSE) -> Valentina Alejandra Lopez Romero | F13: =VLOOKUP(Tabla1[[#This Row],[ID_PARTIDO]],Original!$AT$1:$AY$46,4,FALSE) -> Luis Jorge Garcia Camargo | G13: =VLOOKUP(Tabla1[[#This Row],[ID_PARTIDO]],Original!$AT$1:$AY$46,5,FALSE) -> Nikol sofia avendaño | H13: IZQUIERDA | I13: DERECHA | J13: IZQUIERDA | K13: DERECHA | L13: 1 | M13: 0
... A25: 3 | B25: 1 | C25: 12 | D25: =VLOOKUP(Tabla1[[#This Row],[ID_PARTIDO]],Original!$AT$1:$AY$46,2,FALSE) -> María José Cifuentes | E25: =VLOOKUP(Tabla1[[#This Row],[ID_PARTIDO]],Original!$AT$1:$AY$46,3,FALSE) -> Santiago Urrego Rodríguez | F25: =VLOOKUP(Tabla1[[#This Row],[ID_PARTIDO]],Original!$AT$1:$AY$46,4,FALSE) -> Jonatan Nicolas Marmolejo Lopez | G25: =VLOOKUP(Tabla1[[#This Row],[ID_PARTIDO]],Original!$AT$1:$AY$46,5,FALSE) -> Fermin Alejandro Escalona Guillen | H25: DERECHA | I25: IZQUIERDA | J25: IZQUIERDA | K25: DERECHA | L25: 0 | M25: 1
A26: 9 | B26: 1 | C26: 1 | D26: =VLOOKUP(Tabla1[[#This Row],[ID_PARTIDO]],Original!$AT$1:$AY$46,2,FALSE) -> Santiago Gutiérrez de Piñeres Barbosa | E26: =VLOOKUP(Tabla1[[#This Row],[ID_PARTIDO]],Original!$AT$1:$AY$46,3,FALSE) -> Santiago Peña Beltran | F26: =VLOOKUP(Tabla1[[#This Row],[ID_PARTIDO]],Original!$AT$1:$AY$46,4,FALSE) -> Tomas Barrios Guevara | G26: =VLOOKUP(Tabla1[[#This Row],[ID_PARTIDO]],Original!$AT$1:$AY$46,5,FALSE) -> César Camilo Díaz Cufiño | H26: IZQUIERDA | I26: DERECHA | J26: IZQUIERDA | K26: DERECHA | L26: | | M26: 0
A27: 9 | B27: 1 | C27: 2 | D27: =VLOOKUP(Tabla1[[#This Row],[ID_PARTIDO]],Original!$AT$1:$AY$46,2,FALSE) -> Santiago Gutiérrez de Piñeres Barbosa | E27: =VLOOKUP(Tabla1[[#This Row],[ID_PARTIDO]],Original!$AT$1:$AY$46,3,FALSE) -> Santiago Peña Beltran | F27: =VLOOKUP(Tabla1[[#This Row],[ID_PARTIDO]],Original!$AT$1:$AY$46,4,FALSE) -> Tomas Barrios Guevara | G27: =VLOOKUP(Tabla1[[#This Row],[ID_PARTIDO]],Original!$AT$1:$AY$46,5,FALSE) -> César Camilo Díaz Cufiño | H27: IZQUIERDA | I27: DERECHA | J27: IZQUIERDA | K27: DERECHA | L27: 0 | M27: 1
A28: 9 | B28: 1 | C28: 3 | D28: =VLOOKUP(Tabla1[[#This Row],[ID_PARTIDO]],Original!$AT$1:$AY$46,2,FALSE) -> Santiago Gutiérrez de Piñeres Barbosa | E28: =VLOOKUP(Tabla1[[#This Row],[ID_PARTIDO]],Original!$AT$1:$AY$46,3,FALSE) -> Santiago Peña Beltran | F28: =VLOOKUP(Tabla1[[#This Row],[ID_PARTIDO]],Original!$AT$1:$AY$46,4,FALSE) -> Tomas Barrios Guevara | G28: =VLOOKUP(Tabla1[[#This Row],[ID_PARTIDO]],Original!$AT$1:$AY$46,5,FALSE) -> César Camilo Díaz Cufiño | H28: IZQUIERDA | I28: DERECHA | J28: IZQUIERDA | K28: DERECHA | L28: 1 | M28: 0
A29: 9 | B29: 1 | C29: 4 | D29: =VLOOKUP(Tabla1[[#This Row],[ID_PARTIDO]],Original!$AT$1:$AY$46,2,FALSE) -> Santiago Gutiérrez de Piñeres Barbosa | E29: =VLOOKUP(Tabla1[[#This Row],[ID_PARTIDO]],Original!$AT$1:$AY$46,3,FALSE) -> Santiago Peña Beltran | F29: =VLOOKUP(Tabla1[[#This Row],[ID_PARTIDO]],Original!$AT$1:$AY$46,4,FALSE) -> Tomas Barrios Guevara | G29: =VLOOKUP(Tabla1[[#This Row],[ID_PARTIDO]],Original!$AT$1:$AY$46,5,FALSE) -> César Camilo Díaz Cufiño | H29: IZQUIERDA | I29: DERECHA | J29: IZQUIERDA | K29: DERECHA | L29: 0 | M29: 1
A30: 9 | B30: 1 | C30: 5 | D30: =VLOOKUP(Tabla1[[#This Row],[ID_PARTIDO]],Original!$AT$1:$AY$46,2,FALSE) -> Santiago Gutiérrez de Piñeres Barbosa | E30: =VLOOKUP(Tabla1[[#This Row],[ID_PARTIDO]],Original!$AT$1:$AY$46,3,FALSE) -> Santiago Peña Beltran | F30: =VLOOKUP(Tabla1[[#This Row],[ID_PARTIDO]],Original!$AT$1:$AY$46,4,FALSE) -> Tomas Barrios Guevara | G30: =VLOOKUP(Tabla1[[#This Row],[ID_PARTIDO]],Original!$AT$1:$AY$46,5,FALSE) -> César Camilo Díaz Cufiño | H30: IZQUIERDA | I30: DERECHA | J30: IZQUIERDA | K30: DERECHA | L30: 1 | M30: 0
A31: 9 | B31: 1 | C31: 6 | D31: =VLOOKUP(Tabla1[[#This Row],[ID_PARTIDO]],Original!$AT$1:$AY$46,2,FALSE) -> Santiago Gutiérrez de Piñeres Barbosa | E31: =VLOOKUP(Tabla1[[#This Row],[ID_PARTIDO]],Original!$AT$1:$AY$46,3,FALSE) -> Santiago Peña Beltran | F31: =VLOOKUP(Tabla1[[#This Row],[ID_PARTIDO]],Original!$AT$1:$AY$46,4,FALSE) -> Tomas Barrios Guevara | G31: =VLOOKUP(Tabla1[[#This Row],[ID_PARTIDO]],Original!$AT$1:$AY$46,5,FALSE) -> César Camilo Díaz Cufiño | H31: IZQUIERDA | I31: DERECHA | J31: IZQUIERDA | K31: DERECHA | L31: 0 | M31: 1
A32: 9 | B32: 1 | C32: 7 | D32: =VLOOKUP(Tabla1[[#This Row],[ID_PARTIDO]],Original!$AT$1:$AY$46,2,FALSE) -> Santiago Gutiérrez de Piñeres Barbosa | E32: =VLOOKUP(Tabla1[[#This Row],[ID_PARTIDO]],Original!$AT$1:$AY$46,3,FALSE) -> Santiago Peña Beltran | F32: =VLOOKUP(Tabla1[[#This Row],[ID_PARTIDO]],Original!$AT$1:$AY$46,4,FALSE) -> Tomas Barrios Guevara | G32: =VLOOKUP(Tabla1[[#This Row],[ID_PARTIDO]],Original!$AT$1:$AY$46,5,FALSE) -> César Camilo Díaz Cufiño | H32: IZQUIERDA | I32: DERECHA | J32: IZQUIERDA | K32: DERECHA | L32: 1 | M32: 0
